2025-10-23 13:52:24,889 INFO    MainThread:149 [wandb_setup.py:_flush():81] Current SDK version is 0.22.2
2025-10-23 13:52:24,889 INFO    MainThread:149 [wandb_setup.py:_flush():81] Configure stats pid to 149
2025-10-23 13:52:24,889 INFO    MainThread:149 [wandb_setup.py:_flush():81] Loading settings from /root/.config/wandb/settings
2025-10-23 13:52:24,889 INFO    MainThread:149 [wandb_setup.py:_flush():81] Loading settings from /workspace/wandb/settings
2025-10-23 13:52:24,889 INFO    MainThread:149 [wandb_setup.py:_flush():81] Loading settings from environment variables
2025-10-23 13:52:24,889 INFO    MainThread:149 [wandb_init.py:setup_run_log_directory():705] Logging user logs to /workspace/wandb/run-20251023_135224-zh2nsk6w/logs/debug.log
2025-10-23 13:52:24,889 INFO    MainThread:149 [wandb_init.py:setup_run_log_directory():706] Logging internal logs to /workspace/wandb/run-20251023_135224-zh2nsk6w/logs/debug-internal.log
2025-10-23 13:52:24,890 INFO    MainThread:149 [wandb_init.py:init():832] calling init triggers
2025-10-23 13:52:24,890 INFO    MainThread:149 [wandb_init.py:init():837] wandb.init called with sweep_config: {}
config: {'seq_length': 10, 'vocab_size': 3, 'num_episodes': 1000, 'learning_rate': 0.0001, 'gamma': 0.99, 'epsilon_start': 1.0, 'epsilon_end': 0.01, 'epsilon_decay': 0.995, 'buffer_size': 10000, 'batch_size': 1024, 'target_update_freq': 10, 'architecture': 'MiniTransformer', 'd_model': 64, 'nhead': 4, 'num_layers': 2, 'dim_feedforward': 128, 'max_seq_len': 128, '_wandb': {}}
2025-10-23 13:52:24,890 INFO    MainThread:149 [wandb_init.py:init():880] starting backend
2025-10-23 13:52:25,093 INFO    MainThread:149 [wandb_init.py:init():883] sending inform_init request
2025-10-23 13:52:25,095 INFO    MainThread:149 [wandb_init.py:init():891] backend started and connected
2025-10-23 13:52:25,095 INFO    MainThread:149 [wandb_init.py:init():961] updated telemetry
2025-10-23 13:52:25,097 INFO    MainThread:149 [wandb_init.py:init():985] communicating run to backend with 90.0 second timeout
2025-10-23 13:52:25,593 INFO    MainThread:149 [wandb_init.py:init():1036] starting run threads in backend
2025-10-23 13:52:25,680 INFO    MainThread:149 [wandb_run.py:_console_start():2509] atexit reg
2025-10-23 13:52:25,680 INFO    MainThread:149 [wandb_run.py:_redirect():2357] redirect: wrap_raw
2025-10-23 13:52:25,681 INFO    MainThread:149 [wandb_run.py:_redirect():2426] Wrapping output streams.
2025-10-23 13:52:25,681 INFO    MainThread:149 [wandb_run.py:_redirect():2449] Redirects installed.
2025-10-23 13:52:25,682 INFO    MainThread:149 [wandb_init.py:init():1076] run started, returning control to user process
2025-10-23 13:53:34,997 INFO    wandb-AsyncioManager-main:149 [service_client.py:_forward_responses():80] Reached EOF.
2025-10-23 13:53:34,998 INFO    wandb-AsyncioManager-main:149 [mailbox.py:close():137] Closing mailbox, abandoning 1 handles.
2025-10-23 13:53:35,360 ERROR   MainThread:149 [redirect.py:_on_write():664] [all runs] error in stderr callback
Traceback (most recent call last):
  File "/usr/local/lib/python3.12/dist-packages/wandb/sdk/lib/redirect.py", line 662, in _on_write
    cb(written_data)
  File "/usr/local/lib/python3.12/dist-packages/wandb/sdk/wandb_run.py", line 2436, in <lambda>
    lambda data: self._console_raw_callback("stderr", data),
                 ^^^^^^^^^^^^^^^^^^^^^^^^^^^^^^^^^^^^^^^^^^
  File "/usr/local/lib/python3.12/dist-packages/wandb/sdk/wandb_run.py", line 399, in wrapper
    return func(self, *args, **kwargs)
           ^^^^^^^^^^^^^^^^^^^^^^^^^^^
  File "/usr/local/lib/python3.12/dist-packages/wandb/sdk/wandb_run.py", line 457, in wrapper_fn
    return func(self, *args, **kwargs)
           ^^^^^^^^^^^^^^^^^^^^^^^^^^^
  File "/usr/local/lib/python3.12/dist-packages/wandb/sdk/wandb_run.py", line 1595, in _console_raw_callback
    self._backend.interface.publish_output_raw(name, data)
  File "/usr/local/lib/python3.12/dist-packages/wandb/sdk/interface/interface.py", line 802, in publish_output_raw
    self._publish_output_raw(o)
  File "/usr/local/lib/python3.12/dist-packages/wandb/sdk/interface/interface_shared.py", line 37, in _publish_output_raw
    self._publish(rec)
  File "/usr/local/lib/python3.12/dist-packages/wandb/sdk/interface/interface_sock.py", line 43, in _publish
    self._asyncer.run(lambda: self._client.publish(request))
  File "/usr/local/lib/python3.12/dist-packages/wandb/sdk/lib/asyncio_manager.py", line 136, in run
    return future.result()
           ^^^^^^^^^^^^^^^
  File "/usr/lib/python3.12/concurrent/futures/_base.py", line 456, in result
    return self.__get_result()
           ^^^^^^^^^^^^^^^^^^^
  File "/usr/lib/python3.12/concurrent/futures/_base.py", line 401, in __get_result
    raise self._exception
  File "/usr/local/lib/python3.12/dist-packages/wandb/sdk/lib/asyncio_manager.py", line 219, in _wrap
    return await fn()
           ^^^^^^^^^^
  File "/usr/local/lib/python3.12/dist-packages/wandb/sdk/lib/service/service_client.py", line 38, in publish
    await self._send_server_request(request)
  File "/usr/local/lib/python3.12/dist-packages/wandb/sdk/lib/service/service_client.py", line 64, in _send_server_request
    await self._writer.drain()
  File "/usr/lib/python3.12/asyncio/streams.py", line 392, in drain
    await self._protocol._drain_helper()
  File "/usr/lib/python3.12/asyncio/streams.py", line 166, in _drain_helper
    raise ConnectionResetError('Connection lost')
ConnectionResetError: Connection lost
2025-10-23 13:53:35,363 ERROR   MainThread:149 [redirect.py:_on_write():664] [all runs] error in stderr callback
Traceback (most recent call last):
  File "/usr/local/lib/python3.12/dist-packages/wandb/sdk/lib/redirect.py", line 662, in _on_write
    cb(written_data)
  File "/usr/local/lib/python3.12/dist-packages/wandb/sdk/wandb_run.py", line 2436, in <lambda>
    lambda data: self._console_raw_callback("stderr", data),
                 ^^^^^^^^^^^^^^^^^^^^^^^^^^^^^^^^^^^^^^^^^^
  File "/usr/local/lib/python3.12/dist-packages/wandb/sdk/wandb_run.py", line 399, in wrapper
    return func(self, *args, **kwargs)
           ^^^^^^^^^^^^^^^^^^^^^^^^^^^
  File "/usr/local/lib/python3.12/dist-packages/wandb/sdk/wandb_run.py", line 457, in wrapper_fn
    return func(self, *args, **kwargs)
           ^^^^^^^^^^^^^^^^^^^^^^^^^^^
  File "/usr/local/lib/python3.12/dist-packages/wandb/sdk/wandb_run.py", line 1595, in _console_raw_callback
    self._backend.interface.publish_output_raw(name, data)
  File "/usr/local/lib/python3.12/dist-packages/wandb/sdk/interface/interface.py", line 802, in publish_output_raw
    self._publish_output_raw(o)
  File "/usr/local/lib/python3.12/dist-packages/wandb/sdk/interface/interface_shared.py", line 37, in _publish_output_raw
    self._publish(rec)
  File "/usr/local/lib/python3.12/dist-packages/wandb/sdk/interface/interface_sock.py", line 43, in _publish
    self._asyncer.run(lambda: self._client.publish(request))
  File "/usr/local/lib/python3.12/dist-packages/wandb/sdk/lib/asyncio_manager.py", line 136, in run
    return future.result()
           ^^^^^^^^^^^^^^^
  File "/usr/lib/python3.12/concurrent/futures/_base.py", line 456, in result
    return self.__get_result()
           ^^^^^^^^^^^^^^^^^^^
  File "/usr/lib/python3.12/concurrent/futures/_base.py", line 401, in __get_result
    raise self._exception
  File "/usr/local/lib/python3.12/dist-packages/wandb/sdk/lib/asyncio_manager.py", line 219, in _wrap
    return await fn()
           ^^^^^^^^^^
  File "/usr/local/lib/python3.12/dist-packages/wandb/sdk/lib/service/service_client.py", line 38, in publish
    await self._send_server_request(request)
  File "/usr/local/lib/python3.12/dist-packages/wandb/sdk/lib/service/service_client.py", line 64, in _send_server_request
    await self._writer.drain()
  File "/usr/lib/python3.12/asyncio/streams.py", line 392, in drain
    await self._protocol._drain_helper()
  File "/usr/lib/python3.12/asyncio/streams.py", line 166, in _drain_helper
    raise ConnectionResetError('Connection lost')
ConnectionResetError: Connection lost
